Traceback (most recent call last):
  File "C:\ProgramData\Anaconda3\lib\site-packages\jupyter_cache\executors\utils.py", line 51, in single_nb_execution
    executenb(
  File "C:\ProgramData\Anaconda3\lib\site-packages\nbclient\client.py", line 1112, in execute
    return NotebookClient(nb=nb, resources=resources, km=km, **kwargs).execute()
  File "C:\ProgramData\Anaconda3\lib\site-packages\nbclient\util.py", line 74, in wrapped
    return just_run(coro(*args, **kwargs))
  File "C:\ProgramData\Anaconda3\lib\site-packages\nbclient\util.py", line 53, in just_run
    return loop.run_until_complete(coro)
  File "C:\ProgramData\Anaconda3\lib\asyncio\base_events.py", line 642, in run_until_complete
    return future.result()
  File "C:\ProgramData\Anaconda3\lib\site-packages\nbclient\client.py", line 553, in async_execute
    await self.async_execute_cell(
  File "C:\ProgramData\Anaconda3\lib\site-packages\nbclient\client.py", line 857, in async_execute_cell
    self._check_raise_for_error(cell, exec_reply)
  File "C:\ProgramData\Anaconda3\lib\site-packages\nbclient\client.py", line 760, in _check_raise_for_error
    raise CellExecutionError.from_cell_and_msg(cell, exec_reply_content)
nbclient.exceptions.CellExecutionError: An error occurred while executing the following cell:
------------------
%load_ext autoreload
%autoreload 2

from Ubidots_library_acruz import Ubidots

import warnings
warnings.filterwarnings("ignore")
import pandas as pd
import numpy as np
from datetime import datetime


from dotenv import load_dotenv
from dotenv import dotenv_values

dotenv_values(".env")
load_dotenv()
_TOKEN = os.getenv("_token")
BASELINE_DATE_INTERVAL = [os.getenv("_BASELINE_DATE_INTERVAL_START"), os.getenv("_BASELINE_DATE_INTERVAL_END")]
STUDY_DATE_INTERVAL = [os.getenv("_STUDY_DATE_INTERVAL_START"), os.getenv("_STUDY_DATE_INTERVAL_END")]

import requests
import json

from matplotlib import pyplot as plt
from matplotlib.ticker import PercentFormatter
import seaborn as sns


from sys import exit

import os

------------------

[1;31m---------------------------------------------------------------------------[0m
[1;31mNameError[0m                                 Traceback (most recent call last)
[1;32mC:\Users\JCGONZ~1\AppData\Local\Temp/ipykernel_29452/1826514594.py[0m in [0;36m<module>[1;34m[0m
[0;32m     16[0m [0mdotenv_values[0m[1;33m([0m[1;34m".env"[0m[1;33m)[0m[1;33m[0m[1;33m[0m[0m
[0;32m     17[0m [0mload_dotenv[0m[1;33m([0m[1;33m)[0m[1;33m[0m[1;33m[0m[0m
[1;32m---> 18[1;33m [0m_TOKEN[0m [1;33m=[0m [0mos[0m[1;33m.[0m[0mgetenv[0m[1;33m([0m[1;34m"_token"[0m[1;33m)[0m[1;33m[0m[1;33m[0m[0m
[0m[0;32m     19[0m [0mBASELINE_DATE_INTERVAL[0m [1;33m=[0m [1;33m[[0m[0mos[0m[1;33m.[0m[0mgetenv[0m[1;33m([0m[1;34m"_BASELINE_DATE_INTERVAL_START"[0m[1;33m)[0m[1;33m,[0m [0mos[0m[1;33m.[0m[0mgetenv[0m[1;33m([0m[1;34m"_BASELINE_DATE_INTERVAL_END"[0m[1;33m)[0m[1;33m][0m[1;33m[0m[1;33m[0m[0m
[0;32m     20[0m [0mSTUDY_DATE_INTERVAL[0m [1;33m=[0m [1;33m[[0m[0mos[0m[1;33m.[0m[0mgetenv[0m[1;33m([0m[1;34m"_STUDY_DATE_INTERVAL_START"[0m[1;33m)[0m[1;33m,[0m [0mos[0m[1;33m.[0m[0mgetenv[0m[1;33m([0m[1;34m"_STUDY_DATE_INTERVAL_END"[0m[1;33m)[0m[1;33m][0m[1;33m[0m[1;33m[0m[0m

[1;31mNameError[0m: name 'os' is not defined
NameError: name 'os' is not defined

