Traceback (most recent call last):
  File "C:\Users\jkgv1\.conda\envs\Ubidots\lib\site-packages\jupyter_cache\executors\utils.py", line 51, in single_nb_execution
    executenb(
  File "C:\Users\jkgv1\.conda\envs\Ubidots\lib\site-packages\nbclient\client.py", line 1204, in execute
    return NotebookClient(nb=nb, resources=resources, km=km, **kwargs).execute()
  File "C:\Users\jkgv1\.conda\envs\Ubidots\lib\site-packages\nbclient\util.py", line 84, in wrapped
    return just_run(coro(*args, **kwargs))
  File "C:\Users\jkgv1\.conda\envs\Ubidots\lib\site-packages\nbclient\util.py", line 62, in just_run
    return loop.run_until_complete(coro)
  File "C:\Users\jkgv1\.conda\envs\Ubidots\lib\asyncio\base_events.py", line 647, in run_until_complete
    return future.result()
  File "C:\Users\jkgv1\.conda\envs\Ubidots\lib\site-packages\nbclient\client.py", line 663, in async_execute
    await self.async_execute_cell(
  File "C:\Users\jkgv1\.conda\envs\Ubidots\lib\site-packages\nbclient\client.py", line 965, in async_execute_cell
    await self._check_raise_for_error(cell, cell_index, exec_reply)
  File "C:\Users\jkgv1\.conda\envs\Ubidots\lib\site-packages\nbclient\client.py", line 862, in _check_raise_for_error
    raise CellExecutionError.from_cell_and_msg(cell, exec_reply_content)
nbclient.exceptions.CellExecutionError: An error occurred while executing the following cell:
------------------
%load_ext autoreload
%autoreload 2

from Ubidots_library_acruz import Ubidots

import warnings
warnings.filterwarnings("ignore")
import pandas as pd
import numpy as np
from datetime import datetime

from dotenv import load_dotenv
from dotenv import dotenv_values
dotenv_values(".env")
load_dotenv()
_TOKEN = os.getenv("_token")
BASELINE_DATE_INTERVAL = [os.getenv("_BASELINE_DATE_INTERVAL_START"), os.getenv("_BASELINE_DATE_INTERVAL_END")]
STUDY_DATE_INTERVAL = [os.getenv("_STUDY_DATE_INTERVAL_START"), os.getenv("_STUDY_DATE_INTERVAL_END")]

import requests
import json

from matplotlib import pyplot as plt
from matplotlib.ticker import PercentFormatter
import seaborn as sns


from sys import exit

import os

------------------

[1;31m---------------------------------------------------------------------------[0m
[1;31mNameError[0m                                 Traceback (most recent call last)
Input [1;32mIn [1][0m, in [0;36m<cell line: 16>[1;34m()[0m
[0;32m     14[0m dotenv_values([38;5;124m"[39m[38;5;124m.env[39m[38;5;124m"[39m)
[0;32m     15[0m load_dotenv()
[1;32m---> 16[0m _TOKEN [38;5;241m=[39m [43mos[49m[38;5;241m.[39mgetenv([38;5;124m"[39m[38;5;124m_token[39m[38;5;124m"[39m)
[0;32m     17[0m BASELINE_DATE_INTERVAL [38;5;241m=[39m [os[38;5;241m.[39mgetenv([38;5;124m"[39m[38;5;124m_BASELINE_DATE_INTERVAL_START[39m[38;5;124m"[39m), os[38;5;241m.[39mgetenv([38;5;124m"[39m[38;5;124m_BASELINE_DATE_INTERVAL_END[39m[38;5;124m"[39m)]
[0;32m     18[0m STUDY_DATE_INTERVAL [38;5;241m=[39m [os[38;5;241m.[39mgetenv([38;5;124m"[39m[38;5;124m_STUDY_DATE_INTERVAL_START[39m[38;5;124m"[39m), os[38;5;241m.[39mgetenv([38;5;124m"[39m[38;5;124m_STUDY_DATE_INTERVAL_END[39m[38;5;124m"[39m)]

[1;31mNameError[0m: name 'os' is not defined
NameError: name 'os' is not defined

